Workbook

Sheet 様式第１号 
B2: 整理 番号 | F2: － 初等 ・中等 ・高等 ・他 － | Y2: ※ 事務局使用欄 | AN2: 整理 番号 | AR2: － 初等 ・中等 ・高等 ・他 － | BK2: ※ 事務局使用欄
B4: 様式第１号 | AN4: 様式第１号
C5: 令和 | F5: 8 | G5: 年度（公財）福島県学術教育振興財団助成対象事業実施計画書 | AO5: 令和 | AR5: =F5 -> 8 | AS5: 年度（公財）福島県学術教育振興財団助成対象事業実施計画書
B7: １ 提出年月日 | I7: 令和 | K7: 8 | N7: 年 | O7: 1 | S7: 月 | T7: 6 | X7: 日 | AN7: １ 提出年月日 | AU7: 令和 | AZ7: 年 | BE7: 月 | BJ7: 日
B8: ２ 事 業 名 | I8: 土の健康診断 | AN8: ２ 事 業 名 | AU8: ※継続事業の場合は末尾に何年目の事業なのかを明記すること。 例：（2年目）、３ など
B9: ３ 事業の実施主体 | C9: 団体又は 教育機関の名称 | I9: 公立大学法人会津大学 | AN9: ３ 事業の実施主体 | AO9: 団体又は 教育機関の名称 | AU9: ※記載漏れ・誤りのないようにすること。
C11: 所 在 地 | I11: 〒 | J11: 965 | L11: － | M11: 8580 | P11: 印 | AO11: 所 在 地 | AU11: 〒 | AX11: － | BB11: 印
I12: 福島県会津若松市一箕町鶴賀 | AU12: ※記載漏れ・誤りのないようにすること。
C14: 代表者 | F14: 職 名 | I14: 教授 | AO14: 代表者 | AR14: 職 名 | AU14: ※記載漏れ・誤りのないようにすること。
F15: 氏 名 | I15: （ﾌﾘｶﾞﾅ） | L15: ハミード サジ | AR15: 氏 名
L16: ハミード サジ
B17: (事業実施代表者及び分担者) ４ 事業実施組織 | D17: 氏 名 | J17: 団体(機関)に おける職 | Q17: 役割分担(各人の本年度の事業実施計画に関する 役割分担事項を記入すること） | AN17: (事業実施代表者及び分担者) ４ 事業実施組織 | AP17: 氏 名 | AV17: 団体(機関)に おける職 | BC17: 役割分担(各人の本年度の事業実施計画に関する 役割分担事項を記入すること）
D19: （代表者） | AP19: （代表者） ※いずれも記載漏れのないよう、簡潔かつ分かりやすく記載すること。
D20: =L16 -> ハミード サジ | J20: =I14 -> 教授
D28: 計 | F28: =COUNTA(D20:I27) -> 1 | H28: 名 | AP28: 計 | AR28: =COUNTA(AP20:AU27) -> 0 | AT28: 名
B30: 5 事務担当者 | C30: 職 名 | I30: 会津大学 連携支援係 | AN30: 5 事務担当者 | AO30: 職 名
C31: 氏 名 | I31: （ﾌﾘｶﾞﾅ） | L31: オオシマ ナミキ | AO31: 氏 名 | AY31: ※連絡調整などを行う事務担当者の連絡先を記載。
L32: 大島 なみ紀 | AY32: ※押印を省略しない場合でも、必ず記載すること。
C33: TEL | I33: 0242-37-2149 | AO33: TEL
C34: E-mail | I34: cl-innov@u-aizu.ac.jp | AO34: E-mail
B35: ６ 事業実施期間 | I35: 事業開始（予定）年月日 | R35: 令和 | T35: =F5 -> 8 | V35: 年 | W35: 4 | Y35: 月 | Z35: 1 | AB35: 日 | AN35: ６ 事業実施期間 | AU35: 事業開始（予定）年月日 | BD35: 令和 | BF35: =F5 -> 8 | BH35: 年 | BK35: 月 | BN35: 日
I36: 事業完了（予定）年月日 | R36: 令和 | T36: 11 | V36: 年 | W36: 3 | Y36: 月 | Z36: 31 | AB36: 日 | AU36: 事業完了（予定）年月日 | BD36: 令和 | BH36: 年 | BK36: 月 | BN36: 日
B37: ７ 事業の分類 （次の分類のどれに該当するか、番号をマルで囲んでください。(複数可)） | AN37: ７ 事業の分類 （次の分類のどれに該当するか、番号をマルで囲んでください。(複数可)）
B38: １．調 査 ②．学術研究 ３．研 修 ４．県民の生涯学習機会の拡充活動 | AN38: １．調 査 ２．学術研究 ３．研 修 ４．県民の生涯学習機会の拡充活動
B40: ８ 前年度までの成果 （継続事業のみ記入。応募時点の状況についてわかりやすく記入してください) | AN40: ８ 前年度までの成果 （継続事業のみ記入。応募時点の状況についてわかりやすく記入してください)
AN41: ※ 以下の形式を目安に記載すること。 ①事業成果・・・箇条書きとすること。 ・①の説明 ②事業成果・・・箇条書きとすること。 ・②の説明 （③以降も同じ） ※ 県民に分かるように専門用語の使用は必要最小限とすること。
B49: ９ 事業の目的 （現状を踏まえ、事業の目的（ねらい）を分かりやすく記入してください） | AN49: ９ 事業の目的 （現状を踏まえ、事業の目的（ねらい）を分かりやすく記入してください）
B50: ①誰でも土の状態を測れる仕組みを作る 日本が食料不安に直面する中、土の劣化や土の力の低下は深刻な問題です。この問題への意識を高めるため、誰でも簡単に土の状態を測ってマップ化できる方法を開発・普及させたいと考えています。また、このツールを高校での環境教育に活用し、若い世代に土の劣化や食料安全保障について関心を持ってもらいたいと考えています。 ・現在、土の状態を調べるには、畑を掘って土を採取し、専門機関に送る必要があります。これには時間とお金がかかり、誰でもできるものではありません。 ・私たちのツールは、「土が健康なら植物もよく育ち、葉が甘くなる」という関係に着目しています。葉の糖度（Brix）だけを測定し、AIで土の状態を推定するシステムを構築します。 ・使うのは手で持てる安い糖度計だけ。農家さんがスマホ感覚で葉を測れば、すぐに土の状態が分かり、「今は肥料が必要か？」といった判断がその場でできるようになります。 ②土地の使い方と土の状態の関係を調べる 福島の土を守り、より良くするためには、広い地域で土の状態がどう分布しているか、そして土地の使い方によってどう違うのかを研究する必要があります。この研究を通じて、土を劣化させる主な原因を明らかにし、対策を考えることができます。 ・開発した簡単な測定ツールを使って、様々な農地や森林で現地調査を行います。 ・集めたデータをコンピューターで分析し、土の状態に影響を与える要因を特定します。 ・この結果をもとに、福島の土を守るための具体的な提案を行います。 | AN50: ※ 以下の形式を目安に記載すること。 ①事業目的・・・箇条書きとすること。 ・①の説明 ②事業目的・・・箇条書きとすること。 ・②の説明 （③以降も同じ） ※ 県民に分かるように専門用語の使用は必要最小限とすること。
B71: 10 事業内容 （要望年度における事業の具体的な内容を記入してください） | AN71: 10 事業内容 （要望年度における事業の具体的な内容を記入してください）
B72: ①測定システムの開発と検証 葉の糖度から土の状態を推定するシステムを開発し、その精度を確認します。 ・実験圃場（1.5m×5m×4区画）で、4月から翌年3月まで月1回測定を行います（計12回）。 ・各区画の土（深さ3cmと20cm）の炭素量と、野菜の葉の糖度を測定します。1年間で約200点のデータを収集します。 ・統計分析により、「葉の糖度が高いほど土の炭素量も多い」という関係を検証します。 ②異なる育て方の比較実験 どちらの農法が土にとって良いかをデータで明らかにします。 ・4区画のうち2区画を「自然農法（無肥料・不耕起）」、2区画を「慣行農法（施肥・耕起）」で栽培します。 ・農法以外の条件はすべて統一し、1年間のデータから「どちらが土に多くの炭素を貯められるか」を数値で示します。 ③高校生への環境教育 開発中のツールを使い、高校生に土と食料の関係を学んでもらいます。 ・地元高校と連携し、生徒が糖度計で葉を測る体験授業を実施します。 ・土の健康と食料安全保障について、実データを通じて学ぶ機会を提供します。 | AN72: ※ 以下の形式を目安に記載すること。 ①事業内容・・・箇条書きとすること。 ・①の説明 ②事業内容・・・箇条書きとすること。 ・②の説明 （③以降も同じ） ※ 県民に分かるように専門用語の使用は必要最小限とすること。
B84: 11 事業の効果及び数値目標 （期待できる効果、成果を具体的な数値を用いて記入してください。） | AN84: 11 事業の効果及び数値目標 （期待できる効果、成果を具体的な数値を用いて記入してください。）
B85: ①誰でも使える土壌診断技術の確立・・・土を掘らずに葉を測るだけで土の状態が分かる技術を確立します。 ・年間200サンプルを収集し、葉の糖度と土の炭素量の相関（目標：相関係数0.7以上）を証明します。 ・従来の土壌分析（1回約1万円、2週間）に対し、コストをほぼ0円、時間を即時とする技術を確立します。 ②環境に優しい農業の効果を数値で証明・・・自然農法と慣行農法を比較し、どちらが土に良いかを明確にします。 ・1年間のデータから両農法の土壌炭素貯留量の差を定量的に比較します。 ・環境保全型農業の優位性を示す科学的根拠を提供します。 ③次世代への環境教育の推進・・・高校生を対象とした環境教育プログラムを実施します。 ・年間で少なくとも1校以上と連携し、延べ30名以上の生徒に体験授業を提供します。 ・土の健康と食料安全保障について実データを通じて学ぶ機会を創出します。 ④研究成果の発信 ・今年度中に学会発表1件以上、または学術論文投稿1件以上を行います。 ・地域の農家や関係者向けに報告会を開催します（年1回以上） | AN85: ※ 以下の形式を目安に具体的な数字を用いて記載すること。 ①期待できる効果、成果・・・箇条書きとすること。 ・①の説明 ②期待できる効果、成果・・・箇条書きとすること。 ・②の説明 （③以降も同じ） ※ 県民に分かるように専門用語の使用は必要最小限とすること。
B98: 12 事業の全体計画 （複数年度での計画の場合、年度ごとの計画（取組）を記入してください） | AN98: 12 事業の全体計画 （複数年度での計画の場合、年度ごとの計画（取組）を記入してください）
D99: 初年度 | G99: （令和 | I99: =F5 -> 8 | J99: 年度） | O99: ２年目 | R99: （令和 | T99: =I99+1 -> 9 | U99: 年度） | Z99: ３年目 | AC99: （令和 | AE99: =I99+2 -> 10 | AF99: 年度） | AP99: 初年度 | AS99: （令和 | AU99: ○ | AV99: 年度） | BA99: ２年目 | BD99: （令和 | BF99: ○ | BG99: 年度） | BL99: ３年目 | BO99: （令和 | BQ99: ○ | BR99: 年度）
B100: 目標 | C100: 測定技術の基礎確立と初期データ収集 | N100: 測定精度の向上と適用範囲の拡大 | Y100: 実用化に向けた総合評価と普及活動 | AN100: 目標 | AO100: ※ 箇条書きによる記載を基本とする。 ※ 県民に分かるように専門用語の使用は必要最小限とすること。 ※ １年以上の計画の場合、前年度の反復とならないこと。
B103: 具体的な取組 | C103: ・実験圃場で月1回の定期測定を開始し、年間200サンプルのデータを収集する ・葉の糖度と土の炭素量の関係を統計分析で検証する（相関係数0.7以上を目標） ・自然農法と慣行農法の比較栽培を開始し、初年度のデータを蓄積する ・高校1校以上と連携し、生徒30名以上に体験授業を実施する ・学会発表または学術論文投稿を1件以上行う | N103: ・1年目のデータを基にAI推定モデルを開発し、予測精度を向上させる ・実験圃場以外の複数の農地（少なくとも5カ所以上）で測定を実施し、様々な土壌条件でのデータを収集する ・2年間の比較栽培データから、自然農法と慣行農法の土壌炭素貯留量の差を明確化する ・高校2校以上と連携し、教育プログラムを拡充する（延べ60名以上） ・測定マニュアルの初版を作成し、農家向けの試験運用を開始する ・研究成果を地域報告会で発表する | Y103: ・3年間の全データを統合し、測定システムの最終評価を行う ・開発したAIモデルの実用性を検証し、スマートフォンアプリ等の実用化を検討する ・福島県内の様々な土地利用パターン（農地、森林など）における土壌状態の分布マップを作成する ・高校3校以上と連携し、環境教育プログラムを定着させる（延べ100名以上） ・測定マニュアルの完成版を作成し、農家や教育機関に配布する ・3年間の総合成果を学会発表および学術論文として公表する ・地域の農家、行政、教育関係者を対象とした最終報告会を開催し、今後の普及計画を提示する | AN103: 具体的な取組
B113: 13 要望年度の事業スケジュール （予定スケジュールを記入してください） | AN113: 13 要望年度の事業スケジュール （予定スケジュールを記入してください）
B114: ４月 | D114: ・実験圃場の準備と栽培開始 ・測定機器（糖度計等）の調達 ・高校との連携に向けた打ち合わせ | AN114: ４月 | AP114: ※ 箇条書きによる記載を基本とする。 ※ 年度後半に事業スケジュールが集中しないことが望ましい。 ※ 県民に分かるように専門用語の使用は必要最小限とすること。
B116: ５月 | D116: ・第1回測定（土壌サンプル採取、葉の糖度測定） ・データ記録システムの構築 | AN116: ５月
B118: ６月 | D118: ・第2回測定 ・高校での第1回体験授業の実施 | AN118: ６月
...

Sheet 様式第１号(別紙１）
B1: 整理 番号 | F1: － 初等 ・中等 ・高等 ・他 － | AA1: ※ 事務局使用欄 | BH1: 整理 番号 | BL1: － 初等 ・中等 ・高等 ・他 － | CG1: ※ 事務局使用欄
B3: 様式第１号（別紙１） | BH3: 様式第１号（別紙1）
B4: 助成対象事業実施計画書 事業実施経費予算内訳書
BC5: （単位 円） | DI5: （単位 円）
B6: 区分 | L6: 積算額の内訳 | AC6: 使途（必要とする理由） | AT6: 小計 | BA6: 合計 | BH6: 区分 | BR6: 積算額の内訳 | CI6: 使途（必要とする理由） | CZ6: 小計 | DG6: 合計
B7: 設備備品費 | BA7: =SUM(AT7:AZ13) -> 0 | BH7: 設備備品費 | DG7: =SUM(CZ7:DF13) -> 0
B14: 旅 費 | BA14: =SUM(AT14:AZ21) -> 0 | BH14: 旅 費 | DG14: =SUM(CZ14:DF21) -> 0
B22: 報償費 | BA22: =SUM(AT22:AZ29) -> 0 | BH22: 報償費 | DG22: =SUM(CZ22:DF29) -> 0
B30: その他の経費 | E30: 委託料 | L30: 土の有機炭素含有量測定（有機炭素） 18,000円／検体 × 48検体（※消費税別） | AC30: 研究に必要な土壌有機炭素量の把握・評価のため、外部機関へ分析を委託する。 | AT30: 864000 | BA30: =SUM(AT30:AZ33) -> 864000 | BH30: その他の経費 | DG30: =SUM(CZ30:DF33) -> 0
E34: 賃金 | L34: リサーチ・アシスタント（RA）謝金 会津大学の博士課程生 1300円／時間 × 480時間 | AC34: 本研究を円滑に遂行するため、文献調査、データ整理、実験補助等の研究補助業務を行うリサーチ・アシスタントを配置する必要がある。これらの業務には一定の作業時間を要することから、会津大学の規程に基づき、約480時間分の謝金を計上する。 | AT34: 624000 | BA34: =SUM(AT34:AZ37) -> 624000 | DG34: =SUM(CZ34:DF37) -> 0
BA38: =SUM(AT38:AZ41) -> 0 | DG38: =SUM(CZ38:DF41) -> 0
BA42: =SUM(AT42:AZ45) -> 0 | DG42: =SUM(CZ42:DF45) -> 0
BA46: =SUM(AT46:AZ49) -> 0 | DG46: =SUM(CZ46:DF49) -> 0
C50: その他の経費計 | BA50: =SUM(BA30:BF49) -> 1488000 | BI50: その他の経費計 | DG50: =SUM(DG30:DL49) -> 0
B51: 支出合計 | BA51: =BA7+BA14+BA22+BA50 -> 1488000 | BH51: 支出合計 | DG51: =DG7+DG14+DG22+DG50 -> 0
B53: 財源内訳 | E53: 区 分 | P53: 金 額 | AC53: ※ 留意事項 | BH53: 財源内訳 | BK53: 区 分 | BV53: 金 額 | CI53: ※ 留意事項
E54: 財団助成金 | P54: 1488000 | AC54: ア 「積算額の内訳」の欄には、財源にかかわらず当該事業の経費の全額を記入すること。 | BK54: 財団助成金 | BV54: ※必ず記載すること。 | CI54: ア 「積算額の内訳」の欄には、財源にかかわらず当該事業の経費の全額を記入すること。
E55: 自己負担金 | P55: 0 | AC55: イ 「財源内訳」の欄には、会費、自己負担金、借入金等があれば、その全額を記入すること。 | BK55: 自己負担金 | CI55: イ 「財源内訳」の欄には、会費、自己負担金、借入金等があれば、その全額を記入すること。
AC56: ウ 簡潔でわかりやすく、かつ、正確に記入するとともに、記入漏れがないよう十分注意すること。 | CI56: ウ 簡潔でわかりやすく、かつ、正確に記入するとともに、記入漏れがないよう十分注意すること。
E57: 計 | P57: =SUM(P54:W56) -> 1488000 | AC57: エ 見積書の写し等、経費の算出根拠となる書類を添付すること。 | BK57: 計 | BV57: =SUM(BV54:CC56) -> 0 | CI57: エ 見積書の写し等、経費の算出根拠となる書類を添付すること。

Sheet 様式第1号（別紙2）
A1: 様式第1号（別紙2）
B2: 令和 | C2: ='様式第１号 '!F5 -> 8 | D2: 年度応募書類 セルフチェックシート
E3: 団体名 | G3: ='様式第１号 '!I9 -> 公立大学法人会津大学
E4: 代表者 職名/氏名 | G4: ='様式第１号 '!I14 -> 教授 | H4: / | I4: ='様式第１号 '!L16 -> ハミード サジ
A6: No. | B6: 確認事項 | E6: はい （チェック） | F6: いいえ （チェック） | G6: 備考 （いいえの理由等）
A7: 1 | B7: 助成対象事業実施計画書（様式第１号）がある
A8: 2 | B8: 事業実施経費予算内訳書（様式第１号（別紙１））がある
A9: 3 | B9: 応募書類セルフチェックシート（様式第１号（別紙２）（本シート））がある
A10: 4 | B10: 事業内容をわかりやすく１枚にまとめた概念図（ポンチ絵）がある（任意様式） ※継続事業はこれまでの成果を記載する。
A11: 5 | B11: 委託料及び１件の契約金額が税込10万円以上となる見込みの経費について、見積書等の写しがある
A12: 6 | B12: 旅費の金額の根拠となる規程の写しがある | G12: 本事業において旅費は計上していません。
A13: 7 | B13: 報償費の金額の根拠となる規程の写しがある | G13: 本事業において報償費は計上していません。
A14: 8 | B14: その他事業の詳細が分かる補足資料がある | G14: その他の事業を行う予定はございません。
A16: ※１ 応募書類とともに、本シートも提出すること。また、全体を通して漏れや問題の有無等を十分確認したうえで記入・提出すること。
A17: ※２ 備考欄に記載しきれない場合は別紙を添付することも可。
A18: ※３ その他事業の詳細が分かる補足資料を添付することも可。

Sheet 様式第2号
A2: 様式第２号
E4: 令和 | H4: ='様式第１号 '!F5 -> 8 | J4: 年度（公財）福島県学術教育振興財団助成金交付申請書
Z7: （ 番 号 ）
Z8: 令和 | AB8: ='様式第１号 '!F5 -> 8 | AD8: 年 | AG8: 月 | AJ8: 日
C11: 公益財団法人福島県学術教育振興財団代表理事
C14: 申請者 | F14: 団体又は 教育機関の名称
F16: 所 在 地 | L16: 〒 | P16: －
F19: 代表者 | I19: 職 名
I21: 氏 名
F23: 事務 担当者 | I23: 職 名
I25: 氏 名
C29: 下記のとおり助成金の交付を受けたいので、下記のとおり申請します。
B31: 記
B33: 事業名
B36: 交付申請額 | T36: 円
B39: １）事業の目的
B45: ２）事業の概要（本年度分）
B50: ３）事業の成果：数値目標（事業完了予定年度及び各年度に何をどのくらい達成するのかを具体的に記入してください）
B56: 事業完了予定年月日 | K56: 令和 | N56: ='様式第１号 '!F5+1 -> 9 | P56: 年 | R56: 3 | T56: 月 | V56: 31 | X56: 日
B60: 事業実施組織(事業実施代表者及び分担者) | D60: 氏名 | K60: 団体（機関） における職 | R60: 役割分担（本年度の事業実施計画に関する役割分担事項を記入すること） | AJ60: 備 考
D64: （代表者）
D65: =L21 -> 0 | K65: =L19 -> 0
D81: ※ ９名以上の場合は、別紙とすること。
B82: 事業実施経費予算 | D82: 事業費内訳 | F82: 区分 | K82: 積 算 の 基 礎 | AF82: 小 計 （単位：円） | AK82: 合計 （単位：円）
F85: 設備備品費 | AK85: =SUM(AF85:AJ87) -> 0
F88: 旅 費 | AK88: =SUM(AF88:AJ91) -> 0
F92: 報 償 費 | AK92: =SUM(AF92:AJ95) -> 0
F96: その他の経費 | AK96: =SUM(AF96:AJ98) -> 0
AK99: =SUM(AF99:AJ101) -> 0
AK102: =SUM(AF102:AJ104) -> 0
G105: その他の経費 計 | AK105: =SUM(AK96:AN104) -> 0
F106: 合 計 | AK106: =AK85+AK88+AK92+AK105 -> 0
D107: 財源内訳 | F107: 区分 | K107: 金額（単位：円） | R107: 備考
F109: 財団助成金
F113: 計 | K113: =SUM(K109:Q112) -> 0

Sheet 様式第３号
A1: 様式第３号
G2: ○福学振第○号
A3: （事業団体名） | G3: 令和○年○月○日
A4: （実施代表者） 様
F6: （公財）福島県学術教育振興財団 | I6: 印
F7: 代表理事 （代表理事名）
A9: 助成金交付決定通知書
A10: 令和○年○月○日付で申請のあった令和○年度（公財）福島県学術教育振興財団助成事業について、下記のとおり決定しましたのでお知らせします。
A12: なお、概算払を希望する場合は、下記期限までに助成金概算払請求書（様式第９号）をメールまたは郵送で提出願います。
A14: 記
A15: １ 決定内容
A16: （１）交付決定額 | C16: 金 | D16: ○○○○ | E16: 円
A17: （２）事業名 | C17: ○○○○○○○○○○○○
A19: ２ 概算払請求期限
A20: 令和○年○月○日（○）
A21: ※ 上限額は、交付決定額の９割以内（千円未満切捨て）となります。
A23: ３ 交付条件額
A24: （１）申請内容に基づき適正に事業を執行すること。
A25: （２）「公益財団法人福島県学術教育振興財団助成業務規程」及び「助成事業の流れと留意点（令和○年度）」を遵守すること。
A28: ４ その他
A29: 概算払の様式は、当法人のホームページからダウンロードできます。
A30: （URL https://sites.google.com/fcs.ed.jp/fukugakushin/）
I37: （事務担当 ○○ 電話 024-521-7759）

Sheet 様式第４号
A1: 様式第４号
H3: 令和 | K3: ='様式第１号 '!F5 -> 8 | N3: 年度（公財）福島県学術教育振興財団
C4: 助成金変更（中止・廃止）承認申請書
Y6: 令和 | AD6: 年 | AG6: 月 | AJ6: 日
C8: 公益財団法人福島県学術教育振興財団代表理事
C10: 申請者 | F10: 団体又は 教育機関の名称
F12: 所 在 地 | L12: 〒 | P12: －
F15: 代表者 | I15: 職 名
I17: 氏 名
F19: 事務 担当者 | I19: 職 名
I21: 氏 名
B23: 記
B25: 事業名
B28: 計画変更(中止・廃止)の理由(具体的に記載すること。)
B34: 実施内容と効果の変更
B35: 当初計画・交付申請時 | U35: 変更後
B37: 内容： | U37: 内容：
B46: 効果： | U46: 効果：
B54: 事業完了予定年月日 | K54: 変 更 前 | Z54: 変 更 後
K55: 令和 | M55: =様式第2号!$N$56 -> 9 | O55: 年 | Q55: =様式第2号!$R$56 -> 3 | S55: 月 | U55: =様式第2号!$V$56 -> 31 | W55: 日 | Z55: 令和 | AB55: =M55 -> 9 | AD55: 年 | AF55: =Q55 -> 3 | AH55: 月 | AJ55: =U55 -> 31 | AL55: 日
B59: 事業実施組織 (事業実施代表者・分担者) | D59: 変更前 | V59: 変更後
D60: 氏 名 | I60: 団体における職 | O60: 役割分担 | V60: 氏 名 | AA60: 団体における職 | AG60: 役割分担
D69: 計( | H69: ) | I69: 名 | V69: 計( | Z69: ) | AA69: 名
B72: 事業実施経費予算 | D72: 事業費内訳 | F72: 区分 | K72: 金額（単位：円） | Y72: 変更後の事業費の積算内訳
K73: 変更前の額 | R73: 変更後の額
F75: 設備備品費
F78: 小計 | K78: =SUM($K$75:$Q$77) -> 0 | R78: =SUM($R$75:$X$77) -> 0
F79: 旅 費
F82: 小計 | K82: =SUM(K79:Q81) -> 0 | R82: =SUM(R79:$X$81) -> 0
F83: 報 償 費
F86: 小計 | K86: =SUM(K83:Q85) -> 0 | R86: =SUM(R83:X85) -> 0
F87: その他の経費
F96: 小計 | K96: =SUM(K87:Q95) -> 0 | R96: =SUM(R87:X95) -> 0
F97: 計 | K97: =K78+K82+K86+K96 -> 0 | R97: =R78+R82+R86+R96 -> 0
D99: 財源内訳 | F99: 区分 | K99: 金額（単位：円） | Y99: 説明
K100: 変更前の額 | R100: 変更後の額
F101: 財団助成金
F105: 計 | K105: =SUM(K101:Q104) -> 0 | R105: =SUM(R101:X104) -> 0

Sheet 様式第5号
A1: 様式第５号
D3: 令和 | G3: ='様式第１号 '!F5 -> 8 | J3: 年度公益財団法人福島県学術教育振興財団助成金実績報告書
Z6: 令和 | AD6: 年 | AG6: 月 | AJ6: 日
C8: 公益財団法人福島県学術教育振興財団代表理事
C10: 申請者 | F10: 団体又は 教育機関の名称 | L10: =様式第2号!L14 -> 0
F12: 所 在 地 | L12: 〒 | M12: =様式第2号!M16 -> 0 | P12: － | Q12: =様式第2号!Q16 -> 0
L13: =様式第2号!L17 -> 0
F15: 代表者 | I15: 職 名 | L15: =様式第2号!L19 -> 0
I17: 氏 名 | L17: =様式第2号!L21 -> 0
F19: 事務 担当者 | I19: 職 名 | L19: =様式第2号!L23 -> 0
I21: 氏 名 | L21: =様式第2号!L25 -> 0
C24: 令和 | E24: ='様式第１号 '!F5 -> 8 | G24: 年 | H24: 4 | J24: 月 | M24: 日付 | O24: ='様式第１号 '!F5 -> 8 | Q24: 福学振第 | W24: 号により、助成金の
C25: 交付決定を受けた事業が完了したので、下記のとおり報告します。
B27: 記
B29: 事業名 | H29: =様式第2号!H33 -> 0
B32: １．事業実績の概要 （実施した事業の具体的内容を記入してください。確認できる資料等を添付すること。）
B44: ２．事業目的（数値目標）の達成状況（実施した事業の目的達成状況を具体的に記入してください。）
B57: ３.事業の成果（事業実施によって得られた成果、効果を記入してください。）
B69: ４．課題、改善を要する事項等 （本年度の活動結果を踏まえ、目的を達成するための課題、懸案事項、改善を要する事項等について記入してください。）
B81: ５・事業実施組織 (事業実施代表者及び分担者) | D81: 氏名 | K81: 団体(機関) における職 | Q81: 役割分担(本年度の実施事業に係る各構成員の役割分担事項を記入すること） | AK81: 備 考
D84: （代表者）
D85: =L17 -> 0 | K85: =L15 -> 0
D93: 計( | I93: ）名
B95: ６．事業完了年月日 | K95: 令和 | O95: =様式第2号!$N$56 -> 9 | Q95: 年 | S95: =様式第2号!$R$56 -> 3 | U95: 月 | W95: =様式第2号!$V$56 -> 31 | Y95: 日
B98: ７． 事業実施経費決算内訳 | AJ98: （単位：円）
B99: 事業費内訳 | D99: 区分 | M99: 支出の内訳 | AF99: 小計 | AL99: 合計
D100: 設備備品費 | AL100: =SUM(AF100:AK102) -> 0
D103: 旅 費 | AL103: =SUM(AF103:AK106) -> 0
D107: 報償費 | AL107: =SUM(AF107:AK110) -> 0
D111: その他の経費 | AL111: =SUM(AF111:AK114) -> 0
AL115: =SUM(AF115:AK118) -> 0
AL119: =SUM(AF119:AK122) -> 0
AL123: =SUM(AF123:AK126) -> 0
AL127: =SUM(AF127:AK131) -> 0
F131: その他の経費 計 | AL131: =SUM(AL111:AP130) -> 0
D132: 支 出 額 合 計 | AL132: =AL100+AL103+AL107+AL131 -> 0
B133: 財源内訳 | D133: 区 分 | J133: 金 額 | Q133: 説 明
D134: 財団助成金
D137: 計 | J137: =SUM(J134:P136) -> 0
B138: ※ 留意事項
...

Sheet 様式5号（別紙１）
B2: 様式第５号（別紙１）
D4: 令和 | E4: ='様式第１号 '!F5 -> 8 | G4: 年度（公財）福島県学術教育振興財団助成事業成果調書
B6: 団体等情報 | C6: 1 | D6: 団体（機関）名称 | E6: =様式第5号!L10 -> 0
C7: 2 | D7: 所 在 地 | E7: 郵便番号 | M7: =様式第2号!L17 -> 0
E8: 〒 | F8: =様式第2号!M16 -> 0 | H8: － | I8: =様式第2号!Q16 -> 0
C9: 3 | D9: 代 表 者 | E9: 職 名 | H9: =様式第2号!L19 -> 0 | U9: 氏 名 | X9: =様式第2号!L21 -> 0
C10: 4 | D10: 連 絡 先 | E10: 電 話 番 号
E11: メールアドレス
B13: 実施事業に関する内容 | C13: 5 | D13: 事 業 名 | E13: =様式第2号!H33 -> 0
C14: 6 | D14: 事業の目的
C15: ※本年度に実施した 事業の概要
C17: 7 | D17: 事業の概要
C18: ※本年度に実施した 事業の概要
C23: 8 | D23: 事業の成果
C28: 9 | D28: 課題、改善事項
C33: 10 | D33: 今後の活動予定
C37: 11 | D37: その他参考事項
C41: 12 | D41: 事業成果に係る 情報公開場所 | E41: ホームページアドレス
E42: その他関連のあるアドレス等
B44: 事業成果等写真
D57: 写真１の説明 | R57: 写真２の説明

Sheet 成果調書記入要領 
C2: 【成果調書記入要領】
C3: 項 目 | I3: 説 明
C4: 共通事項 | I4: 本調書は、本法人においてＨＰ、報告書等により広く公開するものですので、できるだけ簡潔に、第三者が理解しやすいよう記入してください。 また、本調書は電子メールにより電子データでも提出してください。（PDF等に変換せずにWord形式のままとしてください。）
B5: 1 | C5: 団体（機関）名称 | I5: 助成事業における名称を記入してください。
B6: 2 | C6: 所 在 地 | I6: 助成事業における団体等の所在地を記入してください。
B7: 3 | C7: 代 表 者 | I7: 助成事業における代表者を記入してください。
B8: 4 | C8: 連 絡 先 | I8: 助成事業に関する問合せ先を記入してください。なお、公開を希望しない場合は無記入で結構です。
B9: 5 | C9: 事 業 名 | I9: 助成事業名を記入してください。
B10: 6 | C10: 事業の目的 | I10: 実施計画書（様式第1号）の「７ 事業の目的」をベースに、簡潔に記入してください。
B11: 7 | C11: 事業の概要 | I11: 本年度に実施した事業の概要を記入してください。
B12: 10 | C12: 今後の活動予定 | I12: 助成事業について、引き続き活動を続ける場合は、その内容、スケジュール等の予定を記入してください。
B13: 11 | C13: その他参考事項 | I13: 他団体との連携や、助成事業に関連する特記事項がある場合に記入してください。
B14: 12 | C14: 団体等における 情報公開場所 | I14: 助成事業に関する情報を公開しているHPアドレスやSNSのアカウント名等を記載ください。 例：教員等が所属する機関のHPアドレス、教員等が開設しているHPアドレス等 なお、該当ない場合は無記入としてください。
C15: 事業成果等写真 | I15: 事業の成果や実施状況が分かる写真2枚を貼付してください。 なお、事業成果の公開について写真データは、JPEGで、サイズを100～300KB程度としてください。

Sheet 様式第5号（別紙2）
A1: 様式第5号（別紙２）
B2: 令和 | C2: ='様式第１号 '!F5 -> 8 | D2: 年度実績報告書類 セルフチェックシート
E3: 団体名 | G3: =様式第2号!L14 -> 0
E4: 代表者 職名/氏名 | G4: =様式第2号!L19 -> 0 | H4: / | I4: =様式第2号!L21 -> 0
A6: No. | B6: 確認事項 | E6: はい （チェック） | F6: いいえ （チェック） | G6: 備考 （いいえの理由等）
A7: 1 | B7: 実績報告書(様式第５号)がある
A8: 2 | B8: 助成事業成果調書（様式第５号（別紙１））がある
A9: 3 | B9: 実績報告書類セルフチェックシート（様式第5号（別紙２））（本シート）がある
A10: 4 | B10: 事業成果の自己評価表（様式第６号）がある
A11: 5 | B11: 購入伺いや支出伺い等の、意思決定のわかる書類の写しがある
A12: 6 | B12: 見積書・納品書・請求書・領収書などの、支出の根拠となる書類の写しがある
A13: 7 | B13: 旅行命令書、復命書の写しがある
A14: 8 | B14: 事業の成果が確認できる成果物がある
A15: 9 | B15: 10万円以上の物品購入をした際に、所属する教育機関へ寄付したことがわかる書類の写しがある
A17: ※１ 実績報告に係る書類とともに、本シートも提出すること。また、全体を通して漏れや問題の有無等を十分確認し、整理したうえで記入・提出すること。（単なる集約ではないこと）
A18: ※２ 備考欄に記載しきれない場合は別紙を添付することも可。

Sheet 様式第6号
B1: 様式第6号
B3: 事業成果の自己評価表
B5: 実施年度 | J5: 令和 | L5: ='様式第１号 '!F5 -> 8 | N5: 年度
B6: 団体又は教育 機関の名称 | I6: =様式第2号!L14 -> 0
B7: 代表者名 | I7: 職名 | K7: =様式第2号!L19 -> 0 | Q7: 氏名 | S7: =様式第2号!L21 -> 0
B8: 事業名 | I8: =様式第2号!H33 -> 0
B10: １．目的を達成するために、事業の内容は適切かつ有効であったか。
B11: 計画上の実施内容（メニュー）及び規模 | R11: 実施結果（実績）
AS12: ◎
AS13: 〇
AS14: △
AS15: ×
B17: 自己評価 | I17: 評価の根拠、考え方の説明
B22: ２．必要経費の見込みは適切かつ効果的であったか。
B23: 予算計上した経費・金額 | R23: 実施結果（実績）
B29: 自己評価 | I29: 評価の根拠、考え方の説明
B34: ３．事業スケジュール・進行管理は適切であったか。
B35: 計画上のスケジュール | R35: 実施結果（実績）
B41: 自己評価 | I41: 評価の根拠、考え方の説明
B46: ４．期待した効果、成果を得ることはできたか。
B47: 計画上の効果、成果 | R47: 実施結果（実績）
B53: 自己評価 | I53: 評価の根拠、考え方の説明
B58: ５．上記１～５を踏まえた総合評価
B59: 自己評価 | I59: 評価の根拠、考え方の説明
B64: ※ 各項目とも下記（裏面）の評価基準により評価してください。
B67: 【自己評価の評価基準】
B69: １～４の各項目は、左欄に計画上の内容を簡潔に記入し、右欄に当該計画内容に対応する実績を記入してください。 また、計画と実績を踏まえ、下表の基準により自己評価を選択記入するとともに、評価した根拠や考え方を記入してください。
B74: 項 目 | H74: 評価 | J74: 評 価 の 説 明
B75: １．目的を達成するために、事業内容は適切かつ有効であったか。 | H75: ◎ | J75: 事業内容は合理性を有し、十分適切かつ有効であった。
H76: ○ | J76: 事業内容は合理性を有し、おおむね適切かつ有効であった。
H77: △ | J77: 事業内容の一部に改善の余地が認められた。
H78: × | J78: 事業全体に改善の余地が認められた。
B79: ２．必要経費の見込みは適切かつ効果的であったか。 | H79: ◎ | J79: 所要経費がほぼ計画どおりで、合理的かつ効果的な経費執行となった。
H80: ○ | J80: 一部経費の区分又は額に変更が生じたが、おおむね合理的かつ効果的な経費執行となった。
H81: △ | J81: 当初予定していなかった経費の発生や額の過不足が生じるなど、計画での見込みに多少甘さがあった。
H82: × | J82: 計画に対して大きな過不足が生じた経費があり、適切な見込みではなかった。
B83: ３．事業スケジュール・進行管理は適切であったか。 | H83: ◎ | J83: ほぼ計画どおりの時期に円滑に事業を実施できた。
H84: ○ | J84: 計画と多少スケジュールが前後したものがあったが、おおむね円滑に事業を実施できた。
H85: △ | J85: 計画していた取組は全て年度内に完了できたが、中途で大きな日程変更を余儀なくされるなど、計画スケジュール又は進行管理に課題が残った。
H86: × | J86: スケジュールの関係で年度内に完了できない取組が発生するなど、スケジュール又は進行管理が適切ではなかった。
...

Sheet 様式第７号
A1: 様式第７号
G2: ○福学振第○号
A3: （事業団体名） | G3: 令和○年○月○日
A4: （実施代表者） 様
F6: （公財）福島県学術教育振興財団 | I6: 印
F7: 代表理事 （代表理事名）
A9: 助成金交付額確定通知書
A10: 令和○年○月○日付け○福学振第○号により決定した、（公財）福島県学術教育振興財団助成金について、当財団業務規程第９条第１項に基づき、下記のとおり助成金の額を確定しましたのでお知らせします。
A12: なお、精算額については、助成金精算払請求書（様式第８号）の提出後に精算いたしますので、別途作成のうえ、メールまたは郵送にて事務局まで送付願います。
A14: 記
A15: １ 事業名 | B15: ○○○○○○○○○○○○
A17: ２ 精算額
B18: 区分 | D18: 金額 | F18: 備考
B19: 助成金確定額 | D19: ○○○○円
B20: 概算払額 | D20: ○○○○円
B21: 精算払額 | D21: ○○○○円
B22: （確定額により内容に軽微な変更が生じる場合があります）
A24: ３ 請求書提出期限
A25: 令和○年○月○日（○）まで
A27: ４ その他
A28: （１）添付書類として通帳の両面の写しを添付してください。
A29: （２）振込口座の名義人が、交付決定を受けた団体の代表者以外の者であった場合は、助成金受け入れ事務に係る委任状を提出してください。なお、概算払請求時に既に提出している場合には、その写しを提出してください。
I36: （事務担当 ○○ 電話 024-521-7759）

Sheet 様式第8号
A2: 様式第８号
V4: 令和 | Z4: 年 | AC4: 月 | AF4: 日
A7: 公益財団法人福島県学術教育振興財団 代表理事 様
K10: 【請求者】
K11: 団体等名 | P11: =様式第2号!L14 -> 0
K12: 所在地 | P12: =様式第2号!L17 -> 0
K13: 代表者 | N13: 職名/氏名 | P13: =様式第2号!L19 -> 0 | Y13: / | Z13: =様式第2号!L21 -> 0
K14: 事務 担当者 | N14: 職名/氏名 | P14: =様式第2号!L23 -> 0 | Y14: / | Z14: =様式第2号!L25 -> 0
A16: 助 成 金 精 算 払 請 求 書
B20: 令和 | F20: 年 | I20: 月 | L20: 日付け | O20: 福学振第 | S20: 号により交付額の確定を受けた
B21: （公財）福島県学術教育振興財団助成金について、 | Y21: 円を請求します。
C25: 事業名 | N25: =様式第2号!H33 -> 0
C30: 【助成金振り込み先口座】
C31: 金融機関名 | AB31: 本 店
AB32: 支 店
C33: 口座種別 | K33: 普通 ・ 当座 ・ その他 | S33: 口座番号 （左詰め）
C35: 口座名義（漢字）
C37: 口座名義（カナ）
C40: ※１ 概算払を受けていない場合は、通帳の写しを添付すること。
C41: ※２ 振り込み口座の名義人が、交付決定を受けた団体等の代表者以外の者である場合は、
C42: 助成金請求または受領に係る委任状を提出すること。

Sheet 様式第９号
A2: 様式第９号
V4: 令和 | Z4: 年 | AC4: 月 | AF4: 日
A7: 公益財団法人福島県学術教育振興財団 代表理事 様
K10: 【請求者】
K11: 団体等名 | P11: =様式第2号!L14 -> 0
K12: 所在地 | P12: =様式第2号!L17 -> 0
K13: 代表者 | N13: 職名/氏名 | P13: =様式第2号!L19 -> 0 | Y13: / | Z13: =様式第2号!L21 -> 0
K14: 事務 担当者 | N14: 職名/氏名 | P14: =様式第2号!L23 -> 0 | Y14: / | Z14: =様式第2号!L25 -> 0
A16: 助 成 金 概 算 払 請 求 書
B20: 令和 | D20: ='様式第１号 '!F5 -> 8 | F20: 年 | I20: 月 | L20: 日付け | N20: ='様式第１号 '!F5 -> 8 | O20: 福学振第 | S20: 号により交付の決定を受けた
B21: （公財）福島県学術教育振興財団助成金について、 | Y21: 円を概算払請求します。
C25: 事業名 | N25: =様式第2号!H33 -> 0
C30: 【助成金振り込み先口座】
C31: 金融機関名 | AB31: 本 店
AB32: 支 店
C33: 口座種別 | K33: 普通 ・ 当座 ・ その他 | S33: 口座番号 （左詰め）
C35: 口座名義（漢字）
C37: 口座名義（カナ）
C40: ※１ 概算払請求金額は、交付決定額の９割以内とし、千円未満を切り捨てた額とすること。
D41: 特に必要かつ妥当と認める場合には、上記を上回る追加請求を認める場合があるため、別途相談すること。
C42: ※２ 添付書類として通帳の写しを添付すること。
C43: ※３ 振り込み口座の名義人が、交付決定を受けた団体等の代表者以外の者である場合は、
C44: 助成金請求または受領に係る委任状を提出すること。

Sheet 【参考様式】委任状 
A1: 参考様式 | F1: 令和 | H1: 年 | J1: 月 | L1: 日
A6: 公益財団法人福島県学術教育振興財団
A7: 代表理事
D10: 委任者 | E10: 実施団体名 | F10: =様式第2号!L14 -> 0
E11: 職名/氏名 | F11: =様式第2号!L19 -> 0 | I11: / | J11: =様式第2号!L21 -> 0
D12: 事務 担当者 | E12: 職名/氏名 | F12: =様式第2号!L23 -> 0 | I12: / | J12: =様式第2号!L25 -> 0
A15: 委 任 状
B17: 私は、令和 | D17: ='様式第１号 '!F5 -> 8 | E17: 年度下記助成事業に係る助成金の | O17: 請求
D18: に関する権限を次の者に委任します。 | O18: 受領
O19: 請求および受領
A20: 記
B22: 事業名 | C22: =様式第2号!H33 -> 0
C29: 受任者 | D29: 職名
D30: 氏名
